{
    "type": "bundle",
    "id": "bundle--89324b51-6c28-4ead-9124-8198bcca0150",
    "objects": [
        {
            "type": "vulnerability",
            "spec_version": "2.1",
            "id": "vulnerability--e07db7ae-b9c5-4a9b-84d0-441bc5816555",
            "created_by_ref": "identity--8ce3f695-d5a4-4dc8-9e93-a65af453a31a",
            "created": "2021-03-13T20:11:32.428732Z",
            "modified": "2021-03-13T20:11:32.428732Z",
            "name": "CVE-2010-3494",
            "description": "Race condition in the FTPHandler class in ftpserver.py in pyftpdlib before 0.5.2 allows remote attackers to cause a denial of service (daemon outage) by establishing and then immediately closing a TCP connection, leading to the accept function having an unexpected value of None for the address, or an ECONNABORTED, EAGAIN, or EWOULDBLOCK error, a related issue to CVE-2010-3492.",
            "external_references": [
                {
                    "source_name": "cve",
                    "external_id": "CVE-2010-3494"
                }
            ],
            "object_marking_refs": [
                "marking-definition--62fd3f9b-15f3-4ebc-802c-91fce9536bcf"
            ]
        }
    ]
}